<robot name="four_bar">

<link name="fixed_link">
  <inertial>
    <inertia
        ixx="1.15"
        ixy="0"
        ixz="0"
        iyy="1.15"
        iyz="0"
        izz="1.15">
    </inertia>
    <mass value="1"/>
  </inertial>
</link>

<joint name="joint_l1" type="revolute">
  <parent link="fixed_link"/>
  <child link="l1"/>
  <origin xyz="0 0 0" rpy="0 0 1.2217304763960306"/>
  <axis xyz="0 0 1"/>
  <limit lower="-2.23607" upper="2.23607" effort="100" velocity="10"/>
</joint>
<transmission name="joint_l1_trans">
    <type>transmission_interface/SimpleTransmission</type>
    <actuator name="joint_l1_motor">
        <mechanicalReduction>1</mechanicalReduction>
    </actuator>
    <joint name="joint_l1">
        <hardwareInterface>hardware_interface/EffortJointInterface</hardwareInterface>
    </joint>
</transmission>
<link name="l1">
  <visual>
    <origin xyz="0.150 0 0" rpy="0 1.57 0"/>
    <geometry>
      <cylinder radius="0.01" length="0.300"/>
    </geometry>
    <material name="Green">
      <color rgba="0 1 0 1"/>
    </material>
  </visual>
  <collision>
    <origin xyz="0.150 0 0" rpy="0 1.57 0"/>
    <geometry>
      <cylinder radius="0.01" length="0.300"/>
    </geometry>
  </collision>
  <inertial>
        <inertia
            ixx="0.15"
            ixy="0"
            ixz="0"
            iyy="0.15"
            iyz="0"
            izz="0.15">
        </inertia>
        <mass value="0.1"/>
  </inertial>
</link>

<joint name="joint_l2" type="revolute">
  <parent link="l1"/>
  <child link="l2"/>
  <origin xyz="0.300 0 0" rpy="0 0 -0.4363323129985824"/>
  <axis xyz="0 0 1"/>
  <limit lower="-2.23607" upper="2.23607" effort="100" velocity="10"/>
</joint>
<transmission name="joint_l2_trans">
    <type>transmission_interface/SimpleTransmission</type>
    <actuator name="joint_l2_motor">
        <mechanicalReduction>1</mechanicalReduction>
    </actuator>
    <joint name="joint_l2">
        <hardwareInterface>hardware_interface/PassiveJointInterface</hardwareInterface>
    </joint>
</transmission>
<link name="l2">
  <visual>
    <origin xyz="0.200 0 0" rpy="0 1.57 0"/>
    <geometry>
      <cylinder radius="0.01" length="0.400"/>
    </geometry>
    <material name="Green">
      <color rgba="0 1 0 1"/>
    </material>
  </visual>
  <collision>
    <origin xyz="0.200 0 0" rpy="0 1.57 0"/>
    <geometry>
      <cylinder radius="0.01" length="0.400"/>
    </geometry>
  </collision>
  <inertial>
        <inertia
            ixx="0.15"
            ixy="0"
            ixz="0"
            iyy="0.15"
            iyz="0"
            izz="0.15">
        </inertia>
        <mass value="0.1"/>
    </inertial>
</link>

<joint name="joint_l3" type="fixed">
  <parent link="fixed_link"/>
  <child link="l3"/>
  <origin xyz="0.300 0 0" rpy="0 0 3.14"/>
  <axis xyz="0 0 1"/>
</joint>
<link name="l3">
  <visual>
    <origin xyz="0.15 0 0" rpy="0 1.57 0"/>
    <geometry>
      <cylinder radius="0.01" length="0.300"/>
    </geometry>
    <material name="Green">
      <color rgba="0 1 0 1"/>
    </material>
  </visual>
  <inertial>
    <inertia
        ixx="1.15"
        ixy="0"
        ixz="0"
        iyy="1.15"
        iyz="0"
        izz="1.15">
    </inertia>
    <mass value="1"/>
  </inertial>
</link>

<joint name="joint_l4" type="revolute">
  <parent link="l3"/>
  <child link="l4"/>
  <origin xyz="0 0 0" rpy="0 0 -1.719368242"/>
  <axis xyz="0 0 1"/>
  <limit lower="-2.23607" upper="2.23607" effort="100" velocity="10"/>
</joint>
<transmission name="joint_l4_trans">
    <type>transmission_interface/SimpleTransmission</type>
    <actuator name="joint_l4_motor">
        <mechanicalReduction>1</mechanicalReduction>
    </actuator>
    <joint name="joint_l4">
        <hardwareInterface>hardware_interface/PassiveJointInterface</hardwareInterface>
    </joint>
</transmission>
<link name="l4">
  <visual>
    <origin xyz="0.285 0 0" rpy="0 1.57 0"/>
    <geometry>
      <cylinder radius="0.01" length="0.571"/>
    </geometry>
    <material name="Green">
      <color rgba="0 1 0 1"/>
    </material>
  </visual>
  <collision>
    <origin xyz="0.285 0 0" rpy="0 1.57 0"/>
    <geometry>
      <cylinder radius="0.01" length="0.571"/>
    </geometry>
  </collision>
  <inertial>
        <inertia
            ixx="0.15"
            ixy="0"
            ixz="0"
            iyy="0.15"
            iyz="0"
            izz="0.15">
        </inertia>
        <mass value="0.1"/>
    </inertial>
</link>

<gazebo>
  <joint name="l4_l2" type="revolute">
    <parent>l4</parent>
    <child>l2</child>
    <pose>0.400 0 0 0 0 0</pose>
    <axis>
      <xyz>0 0 1</xyz>
      <limit>
        <lower>-6.2</lower>
        <upper>6.2</upper>
      </limit>
    </axis>
  </joint>
</gazebo>

<gazebo>
  <plugin name="gazebo_ros_control" filename="libgazebo_ros_control.so">
    <robotNamespace>/</robotNamespace>
    <robotSimType>gazebo_ros_control/ClosedLoopHWSim</robotSimType>
  </plugin>
</gazebo>
</robot>